Workbook

Sheet 调研概要
A1: 调研分类 | B1: 调研项目 | C1: 调研结果 | D1: 调研结果备注 | E1: 填写说明 | F1: 填写示例 （调研结果，调研结果备注）
A2: 数据仓库组件（核心） | B2: 数据库品牌及版本（含内核版本） | E2: 填写现网系统的品牌及版本，若存在内核版本，请一并补充 | F2: GP5.13（内核PG8.3.24）
B3: 集群规模/机器配置 | E3: 填写现网系统的机器配置信息 | F3: 2+8 | G3: 单台2*20Core，16*32G内存，18*3.84T硬盘
B4: 数据量 | E4: 填写现网系统的数据量大小 | F4: 100TB
B5: 元数据情况（表、视图、函数等） | E5: 填写现网系统的元数据情况，包括用户、序列、schema、表、视图、函数或存储过程等信息，参考<元数据调研>sheet页 | F5: 表：1300+ 函数：1100+ …… | G5: 详见<元数据调研>sheet页
B6: 非sql语言函数使用情况（重点关注） | E6: 填写现网系统的自定义函数使用到非sql语言的使用情况，如：plpythonu、plperl、plperlu等 | F6: 使用到了plpythonu、plperl、plperlu，分别为18个、247个、8个
B7: 是否存在实时数据的场景 | F7: 否
A8: 数据采集组件（ETL） | B8: 工具名称及版本 | F8: Kettle5.0
B9: 任务数 | F9: 300+
B10: 源业务系统数据库类型 | F10: Oracle为主
B11: 源业务系统个数 | F11: 20+
B12: 支持哪些数据源（是否支持目标库DWS） | F12: 支持DWS
A13: 调度服务组件 | B13: 工具名称及版本 | F13: TaskCTL6.0
B14: 任务数 | F14: 1500+
B15: 调度频率 | F15: 每天下午15点启动一次
B16: 支持哪些数据源（是否支持目标库DWS） | F16: 支持DWS | G16: 小部分任务每小时启动一次
A17: 数据服务组件（API） | B17: 工具名称及版本 | F17: XXXAPI数据服务V1.0
B18: 接口数量 | F18: 200+
B19: 支持哪些数据源（是否支持目标库DWS） | F19: 支持DWS
A20: 数据应用组件（BI等） | B20: 应用数量 | E20: 填写上层数据应用的个数 | F20: 2 | G20: 报表系统、数据实验室等2个应用
B21: 是否由应用厂商进行适配（关注） | F21: 否
B22: [1]应用名称 | F22: 报表系统 | G22: 核心应用1
B23: [1]使用的工具集及版本 | F23: FineBI5.x
B24: [1]数量 | F24: 500+
B25: [2]应用名称 | F25: 数据实验室 | G25: 核心应用2
B26: [2]使用的工具集及版本 | F26: 客户自研
B27: [2]数量 | F27: 200+
B28: [3]应用名称
B29: [3]使用的工具集及版本
B30: [3]数量

Sheet 元数据调研（GP）
A1: 序号 | B1: 元数据分类 | C1: 调研结果：截图或填写数据 | D1: 调研结果示例（GP） | E1: 统计脚本参考（GP）：适配GP5、GP6
A2: 1 | B2: 版本信息 | E2: --查看数据库版本（含内核） SELECT version() AS versions;
A3: 2 | B3: 库实例个数 | E3: --统计数据库实例的个数 SELECT count(1) AS database_cnt FROM pg_catalog.pg_database WHERE datname NOT IN ('template0','template1','gpperfmon','postgres');
A4: 3 | B4: 用户个数 | E4: --统计用户个数 SELECT count(1) AS user_cnt FROM pg_catalog.pg_user;
A5: 4 | B5: 数据类型（当前连接的DB） | E5: --统计数据库实例的数据类型的使用情况 SELECT DISTINCT atttypid::regtype AS data_type FROM pg_catalog.pg_attribute pa INNER JOIN pg_catalog.pg_class pc ON pc.oid = pa.attrelid AND pa.attnum > 0 INNER JOIN pg_catalog.pg_namespace pn ON pn.oid = pc.relnamespace AND pn.nspname NOT IN ('pg_catalog','pg_toast','information_schema','gp_toolkit','pg_bitmapindex','pg_aoseg','gptransfer','gpdbtransfer','mad_sync','oracompat','madlib') ORDER BY 1 ;
A6: 5 | B6: schema个数（当前连接的DB） | E6: --统计schema个数（当前连接的DB） SELECT count(1) AS schema_cnt FROM pg_catalog.pg_namespace WHERE nspname NOT IN ('pg_catalog','pg_toast','information_schema','gp_toolkit','pg_bitmapindex','pg_aoseg','gptransfer','gpdbtransfer','mad_sync','oracompat','madlib') ;
A7: 6 | B7: 序列个数（按schema分组） | E7: --按schema分组统计序列个数 WITH w_sequence AS ( SELECT pn.nspname AS schemaname, COUNT(1) AS sequence_cnt FROM pg_catalog.pg_class pc INNER JOIN pg_catalog.pg_namespace pn ON pn.oid = pc.relnamespace AND pn.nspname NOT IN ('pg_catalog','pg_toast','information_schema','gp_toolkit','pg_bitmapindex','pg_aoseg','gptransfer','gpdbtransfer','mad_sync','oracompat','madlib') WHERE pc.relkind = 'S' GROUP BY pn.nspname ) SELECT * FROM w_sequence UNION ALL SELECT 'total-all' AS schemaname,sum(sequence_cnt) AS sequence_cnt FROM w_sequence ORDER BY 2 DESC NULLS LAST, 1 ;
A8: 7 | B8: 表个数（按schema分组） | E8: --统计表个数（含分区和压缩）、分区表个数、压缩表个数，按schema分组 WITH w_table AS ( SELECT pt.schemaname ,sum(CASE WHEN t2.schemaname = pt.schemaname AND t2.partitiontablename = pt.tablename THEN 0 ELSE 1 END) AS table_cnt --所有表 ,sum(CASE WHEN pp.schemaname = pt.schemaname AND pp.tablename = pt.tablename THEN 1 ELSE 0 END) AS partition_table_cnt --分区表 ,sum(CASE WHEN t3.schemaname = pt.schemaname AND t3.tablename = pt.tablename THEN 1 ELSE 0 END) AS pression_table_cnt --压缩表 FROM pg_catalog.pg_tables pt LEFT JOIN (SELECT DISTINCT schemaname ,tablename FROM pg_catalog.pg_partitions) pp ON pp.tablename = pt.tablename AND pp.schemaname = pt.schemaname LEFT JOIN (SELECT DISTINCT schemaname ,partitiontablename FROM pg_catalog.pg_partitions) t2 ON t2.partitiontablename = pt.tablename AND t2.schemaname = pt.schemaname LEFT JOIN ( --压缩 SELECT pn.nspname AS schemaname, pc.relname AS tablename, pc.reloptions FROM pg_catalog.pg_class pc LEFT JOIN pg_catalog.pg_namespace pn ON pn.oid = pc.relnamespace LEFT JOIN (SELECT DISTINCT schemaname ,tablename FROM pg_catalog.pg_partitions) pp ON pp.tablename = pc.relname AND pp.schemaname = pn.nspname WHERE relstorage = 'c' --压缩表 AND pn.nspname NOT IN ('pg_catalog','pg_toast','information_schema','gp_toolkit','pg_bitmapindex','pg_aoseg','gptransfer','gpdbtransfer','mad_sync','oracompat','madlib') AND pp.tablename IS NOT NULL --剔除分区 ) t3 ON t3.schemaname = pt.schemaname AND t3.tablename = pt.tablename WHERE pt.schemaname NOT IN ('pg_catalog','pg_toast','information_schema','gp_toolkit','pg_bitmapindex','pg_aoseg','gptransfer','gpdbtransfer','mad_sync','oracompat','madlib') GROUP BY pt.schemaname ) SELECT * FROM w_table UNION ALL SELECT 'total-all' AS schemaname,sum(table_cnt) AS table_cnt,sum(partition_table_cnt) AS partition_table_cnt,sum(pression_table_cnt) AS pression_table_cnt FROM w_table ORDER BY 2 DESC NULLS LAST, 1 ;
A9: 8 | B9: 数据量（按database分组） | E9: --按database分组统计数据库实例的数据量 SELECT pd.datname AS dbname, pg_size_pretty(pg_database_size(pd.datname)) AS dbsize FROM pg_catalog.pg_database pd ORDER BY 2 DESC;
A10: 9 | B10: 视图个数（按schema分组） | E10: --统计视图个数，按schema分组 WITH w_view AS ( SELECT schemaname ,count(1) AS view_cnt FROM pg_catalog.pg_views WHERE schemaname NOT IN ('pg_catalog','pg_toast','information_schema','gp_toolkit','pg_bitmapindex','pg_aoseg','gptransfer','gpdbtransfer','mad_sync','oracompat','madlib') GROUP BY schemaname ) SELECT * FROM w_view UNION ALL SELECT 'total-all' AS schemaname,sum(view_cnt) AS view_cnt FROM w_view ORDER BY 2 DESC NULLS LAST, 1 ;
A11: 10 | B11: 函数个数（按schema、language分组） | E11: --统计函数个数，按schema、language分组 WITH w_function AS ( SELECT pn.nspname AS schemaname ,pl.lanname ,count(1) AS function_cnt FROM pg_catalog.pg_proc pp LEFT JOIN pg_catalog.pg_namespace pn ON pn.oid = pp.pronamespace LEFT JOIN pg_catalog.pg_language pl ON pl.oid = pp.prolang WHERE pn.nspname NOT IN ('pg_catalog','pg_toast','information_schema','gp_toolkit','pg_bitmapindex','pg_aoseg','gptransfer','gpdbtransfer','mad_sync','oracompat','madlib') GROUP BY pn.nspname ,pl.lanname ) SELECT * FROM w_function UNION ALL SELECT 'total-all' AS schemaname,'total-all' AS lanname,sum(function_cnt) AS function_cnt FROM w_function ORDER BY 3 DESC NULLS LAST, 2, 1 ;
A12: 11 | B12: 扩展插件使用情况

Sheet 元数据调研（Oracle）
A1: 序号 | B1: 元数据分类 | C1: 调研结果：截图或填写数据 | D1: 调研结果示例（Oracle） | E1: 统计脚本参考（Oracle）：适配11g
A2: 1 | B2: 版本信息 | E2: --查看数据库版本信息 SELECT * FROM v$version;
A3: 2 | B3: 库实例个数 | E3: --统计数据库实例的个数 SELECT count(*) AS database_count FROM v$instance;
A4: 3 | B4: 用户个数 | E4: --统计用户个数（不含系统用户） WITH busi_users AS( SELECT username FROM all_users WHERE username <> 'XS$NULL' AND user_id > (SELECT max(user_id) FROM all_users WHERE username IN ('SCOTT','OWBSYS','OWBSYS_AUDIT','APEX_030200','MGMT_VIEW','SYSMAN')) ) SELECT count(*) AS user_cnt FROM busi_users ;
A5: 4 | B5: 数据类型（当前连接的DB） | E5: --统计数据库实例的数据类型的使用情况 WITH busi_users AS( SELECT username FROM all_users WHERE username <> 'XS$NULL' AND user_id > (SELECT max(user_id) FROM all_users WHERE username IN ('SCOTT','OWBSYS','OWBSYS_AUDIT','APEX_030200','MGMT_VIEW','SYSMAN')) ) SELECT DISTINCT t.data_type FROM all_tab_columns t, busi_users u WHERE t.owner = u.username ORDER BY 1;
A6: 7 | B6: 序列个数（按schema分组） | E6: --按schema分组统计序列个数 WITH busi_users AS( SELECT username FROM all_users WHERE username <> 'XS$NULL' AND user_id > (SELECT max(user_id) FROM all_users WHERE username IN ('SCOTT','OWBSYS','OWBSYS_AUDIT','APEX_030200','MGMT_VIEW','SYSMAN')) ) , w AS ( SELECT t.sequence_owner AS schemaname,COUNT(*) AS sequence_cnt FROM all_sequences t, busi_users u WHERE t.sequence_owner = u.username GROUP BY t.sequence_owner ) SELECT * FROM w UNION ALL SELECT 'total-all' AS schemaname,sum(sequence_cnt) AS sequence_cnt FROM w ORDER BY 2 DESC, 1;
A7: 5 | B7: 表个数（按schema分组） | E7: --按schema分组查询表总个数、分区表个数、有主键/唯一约束的表个数 WITH busi_users AS( SELECT username FROM all_users WHERE username <> 'XS$NULL' AND user_id > (SELECT max(user_id) FROM all_users WHERE username IN ('SCOTT','OWBSYS','OWBSYS_AUDIT','APEX_030200','MGMT_VIEW','SYSMAN')) ) , table_info AS ( SELECT t.owner, t.table_name, 1 AS total_table_num, CASE WHEN t.partitioned = 'YES' THEN 1 ELSE 0 END AS part_table_num FROM all_tables t, busi_users t1 WHERE t.owner = t1.username ) , table_primary AS ( SELECT uc.owner, uc.table_name, 1 AS primary_table FROM all_constraints uc, busi_users u WHERE uc.owner = u.username AND uc.constraint_type IN ('P', 'U') -- P表示主键约束，U表示唯一约束 GROUP BY owner, uc.table_name ) SELECT 'total-all' AS schemaname,sum(total_table_num) AS total_table_num, sum(part_table_num) AS part_table_num, sum(nvl(primary_table, 0)) AS primary_table FROM table_info t LEFT JOIN table_primary p ON t.owner = p.owner AND t.table_name = p.table_name UNION all SELECT t.owner AS schemaname, sum(total_table_num) AS total_table_num, sum(part_table_num) AS part_table_num, sum(nvl(primary_table, 0)) AS primary_table FROM table_info t LEFT JOIN table_primary p ON t.owner = p.owner AND t.table_name = p.table_name GROUP BY t.owner ORDER BY 2 DESC, 1;
A8: 6 | B8: 数据量（按database分组） | E8: --按schema分组统计数据量大小，以MB、GB或TB为单位（不含系统自带的表） WITH busi_users AS( SELECT username FROM all_users WHERE username <> 'XS$NULL' AND user_id > (SELECT max(user_id) FROM all_users WHERE username IN ('SCOTT','OWBSYS','OWBSYS_AUDIT','APEX_030200','MGMT_VIEW','SYSMAN')) ) , w AS ( SELECT t.owner AS schemaname,SUM(bytes) AS data_size,ROUND(SUM(bytes)/1024/1024,2) AS data_size_mb, ROUND(SUM(bytes)/1024/1024/1024,2) AS data_size_gb, ROUND(SUM(bytes)/1024/1024/1024/1024,2) AS data_size_tb FROM dba_segments t, busi_users u WHERE t.owner = u.username GROUP BY t.owner ) SELECT * FROM w UNION ALL SELECT 'total-all' AS schemaname,sum(data_size) AS data_size,sum(data_size_mb) AS data_size_mb,sum(data_size_gb) AS data_size_gb,sum(data_size_tb) AS data_size_tb FROM w ORDER BY 2 DESC, 1;
A9: 8 | B9: 视图个数（按schema分组） | E9: --按schema分组统计视图个数 WITH busi_users AS( SELECT username FROM all_users WHERE username <> 'XS$NULL' AND user_id > (SELECT max(user_id) FROM all_users WHERE username IN ('SCOTT','OWBSYS','OWBSYS_AUDIT','APEX_030200','MGMT_VIEW','SYSMAN')) ) , w AS ( SELECT t.owner AS schemaname, COUNT(*) AS view_cnt FROM all_views t, busi_users u WHERE t.owner = u.username GROUP BY t.owner ) SELECT * FROM w UNION ALL SELECT 'total-all' AS schemaname,sum(view_cnt) AS view_cnt FROM w ORDER BY 2 DESC, 1;
A10: 9 | B10: 函数个数（按schema分组） | E10: --按schema分组统计函数个数 WITH busi_users AS( SELECT username FROM all_users WHERE username <> 'XS$NULL' AND user_id > (SELECT max(user_id) FROM all_users WHERE username IN ('SCOTT','OWBSYS','OWBSYS_AUDIT','APEX_030200','MGMT_VIEW','SYSMAN')) ) , w AS ( SELECT t.owner AS schemaname, COUNT(*) AS function_cnt FROM all_objects t, busi_users u WHERE t.owner = u.username AND t.object_type = 'FUNCTION' GROUP BY t.owner ) SELECT * FROM w UNION ALL SELECT 'total-all' AS schemaname,sum(function_cnt) AS function_cnt FROM w ORDER BY 2 DESC, 1;
A11: 10 | B11: 存储过程个数（按schema分组） | E11: --按schema分组统计存储过程个数 WITH busi_users AS( SELECT username FROM all_users WHERE username <> 'XS$NULL' AND user_id > (SELECT max(user_id) FROM all_users WHERE username IN ('SCOTT','OWBSYS','OWBSYS_AUDIT','APEX_030200','MGMT_VIEW','SYSMAN')) ) , w AS ( SELECT t.owner AS schemaname, COUNT(*) AS procedure_cnt FROM all_objects t, busi_users u WHERE t.owner = u.username AND t.object_type = 'PROCEDURE' GROUP BY t.owner ) SELECT * FROM w UNION ALL SELECT 'total-all' AS schemaname,sum(procedure_cnt) AS procedure_cnt FROM w ORDER BY 2 DESC, 1;
A12: 11 | B12: 同义词个数（按schema分组） | E12: --按schema分组统计同义词个数 WITH busi_users AS( SELECT username FROM all_users WHERE username <> 'XS$NULL' AND user_id > (SELECT max(user_id) FROM all_users WHERE username IN ('SCOTT','OWBSYS','OWBSYS_AUDIT','APEX_030200','MGMT_VIEW','SYSMAN')) ) , w AS ( SELECT t.table_owner AS schemaname, COUNT(*) AS synonyms_cnt FROM all_synonyms t, busi_users u WHERE t.table_owner = u.username GROUP BY t.table_owner ) SELECT * FROM w UNION ALL SELECT 'total-all' AS schemaname,sum(synonyms_cnt) AS synonyms_cnt FROM w ORDER BY 2 DESC, 1;
A13: 12 | B13: 存储包个数（按schema分组） | E13: --统计存储包个数，及其下过程/函数的个数 WITH busi_users AS( SELECT username FROM all_users WHERE username <> 'XS$NULL' AND user_id > (SELECT max(user_id) FROM all_users WHERE username IN ('SCOTT','OWBSYS','OWBSYS_AUDIT','APEX_030200','MGMT_VIEW','SYSMAN')) ) , package_info AS ( SELECT t.owner, COUNT(*) AS package_cnt FROM all_objects t, busi_users u WHERE t.owner = u.username AND t.object_type = 'PACKAGE' GROUP BY t.owner ) , package_sub AS ( SELECT t.owner, COUNT(t.text) AS procedure_cnt FROM all_source t, busi_users u WHERE t.owner = u.username AND t.type = 'PACKAGE' AND (t.text LIKE '%PROCEDURE%' OR t.text LIKE '%FUNCTION%') GROUP BY t.owner ) SELECT t.owner AS schemaname, t.package_cnt, t1.procedure_cnt FROM package_info t, package_sub t1 WHERE t.owner = t1.owner UNION ALL SELECT 'total-all' AS schemaname,sum(package_cnt) AS package_cnt, sum(procedure_cnt) AS procedure_cnt FROM package_info t, package_sub t1 WHERE t.owner = t1.owner ORDER BY 2 DESC, 1;

Sheet 工作量预估
A1: 数仓迁移工作量评估：
A2: 序号 | B2: 项目里程碑 | C2: 项目阶段 | D2: 工作内容 | E2: 工作量预估（人月） | O2: 项目计划（时间、人数）
E3: 工作量评估 | G3: 评估说明（🚨仅限内部使用） | I3: 评估参考示例 （某保险公司GP5） | K3: 评估参考示例 （某基金公司一期） | M3: 评估参考示例 人月试算（某交易所GP5） | O3: 计划汇总 （示例：某保险公司） | S3: 计划明细 （示例：某保险公司）
E4: 人月 | F4: 备注 | G4: 评估建议（参考） | H4: 风险提示 | I4: 人月 | J4: 备注 | K4: 人月 | L4: 备注 | M4: 人月 | N4: 备注 | O4: 时间 (周) | P4: 人数 | Q4: 人周 | R4: 人月 | S4: 第1个月 | T4: 第2个月 | U4: 第3个月 | V4: 第4个月 | W4: 第5个月 | X4: 第6个月 | Y4: 第7个月 | Z4: 第8个月 | AA4: 第9个月 | AB4: 第10个月 | AC4: 第11个月 | AD4: 第12个月 | AE4: 第13个月 | AF4: 第14个月 | AG4: 第15个月 | AH4: 第16个月 | AI4: 第17个月 | AJ4: 第18个月
A5: 1 | B5: 产品交付部署 | C5: 环境信息调研 | D5: 调研硬件、网络、操作系统等基础信息，以及工作机情况（需要远程访问） | G5: 一般由原厂交付团队负责集群规划、安装部署。 10节点以内：1-2周，建议1-2人 10-30节点：2-3周，建议2-3人 30-50节点：3-5周，建议3-5人 50节点以上：另行评估 | I5: =5/5/4 | J5: 1周1人 | K5: =3/5/4 | L5: 3天1人 | M5: =5/5/4 | N5: 1周1人 | O5: 1 | P5: 1 | Q5: =O5*P5 | R5: =SUM(Q5:Q8)/4 | S5: 1
A6: 2 | C6: 集群部署规划 | D6: 设计和规划新集群的部署架构，包括IP、端口、磁盘等。 | I6: =5/5/4 | J6: 1周1人 | K6: =3/5/4 | L6: 3天1人 | M6: =5/5/4 | N6: 1周1人 | O6: 1 | P6: 1 | Q6: =O6*P6 | S6: 1
A7: 3 | C7: 集群安装部署 | D7: 进行新集群的安装前检查、安装部署和参数调优等标准交付流程。 | I7: =5/5/4*2 | J7: 1周2人 | K7: =5/5/4*2 | L7: 1周2人 | M7: =5/5/4*2 | N7: 1周2人 | O7: 1 | P7: 2 | Q7: =O7*P7 | S7: 1
A8: 4 | C8: 集群测试与交付 | D8: 对新集群进行测试和验证，确保正常运行后进行交付验收。 | I8: =5/5/4 | J8: 1周1人 | K8: =5/5/4 | L8: 1周1人 | M8: =5/5/4 | N8: 1周1人 | O8: 1 | P8: 1 | Q8: =O8*P8 | S8: 1
A9: 5 | B9: 数仓迁移准备 | C9: 需求分析阶段 | D9: 调研现有数仓的业务需求和数据结构等现状，明确迁移过程中的关键业务点和数据依赖关系。 | G9: 30TB以下：建议2-3周，2-3人 30TB以上：适当增加 | I9: 0.25 | J9: 1周1人 | K9: =5/5/4 | L9: 1周1人 | M9: 0.25 | N9: 1周1人 | O9: 1 | P9: 1 | Q9: =O9*P9 | R9: =SUM(Q9:Q13)/4 | S9: 1
A10: 6 | C10: 方案设计阶段 | D10: 根据需求分析结果，设计新的数仓架构和迁移方案、应急方案等。 | I10: =5*2*2/5/4 | J10: 2周2人 | K10: =10/5/4 | L10: 2周1人 | M10: =5*2*2/5/4 | N10: 2周2人 | O10: 2 | P10: 2 | Q10: =O10*P10 | S10: 1
A11: 7 | C11: 计划制定阶段 | D11: 确定迁移目标、范围和时间表，制定详细的迁移计划，包括风险评估和资源调配。 | I11: 0.25 | J11: 1周1人 | K11: =3/5/4 | L11: 3天1人 | M11: 0.25 | N11: 1周1人 | O11: 1 | P11: 1 | Q11: =O11*P11 | S11: 1
A12: 8 | C12: 基础环境准备 | D12: 部署新数仓环境所需的工具或组件，包括调度、ETL、BI报表、数据服务等组件及迁移工具。并配置好工作机开发环境及相关网络的权限。 | G12: 30TB以下：建议1周，2-3人 30TB以上：适当增加 | H12: 需客户配合开通相关网络、权限、软硬件上架和部署等准备工作。 | I12: 0.5 | J12: 1周2人 | K12: =5/5/4*2 | L12: 1周2人 | M12: 0.5 | N12: 1周2人 | O12: 1 | P12: 2 | Q12: =O12*P12 | S12: 1
A13: 9 | C13: 预迁移验证阶段 | D13: 检查新数仓环境，根据迁移方案选择合适的业务线开展预迁移验证工作（涵盖迁移实施阶段的所有流程节点），及时发现并修复潜在问题。 | G13: 参考POC测试，建议不少于2周，2-3人，1-2个业务场景。 | H13: 选择1-2个具有代表性的完整业务流程进行预迁移验证。 | I13: =5*4*3/5/4 | J13: 4周3人 | K13: 0 | L13: 2周2人，POC已验证，跳过 | M13: =5*3*3/5/4 | N13: 3周3人 | O13: 4 | P13: 3 | Q13: =O13*P13 | S13: 1 | T13: 1
A14: 10 | B14: 数仓迁移实施 | C14: 业务迁移阶段 | D14: 将现有数仓的业务脚本迁移到新数仓中，包括序列、表、函数、视图等对象。 | G14: 人工适配：假设每人每天平均可适配100张表或15个函数（sql语言，其他语言另行评估，如：每人每天1-2个）或25个视图。其他对象建议1周。 工具+人工：假设效率提升1倍，则每人每天平均可适配200张表或30个函数或50个视图。 | H14: DWS目前不支持plpythonu、plperl、plperlu语言。 评估时可假设每人每天可以改写1-2个成plpgsql。 非PG系数据库函数可假设为每人每天10个。 | I14: =ROUND((8000/100+12000/15+5/25+300/2+5*2)/5/4/2,2) | J14: 8000张表（待确认，含分区为37000个，目前按15%比例为分区表，每个分区表平均30个分区进行剔除），1.2w个函数，5个视图，300个非sql函数，其他对象若干（按1周2人计算），使用工具，假设效率提升1倍 | K14: =ROUND((400/100+300/15+5)/5/4,2) | L14: 400张表、300个函数、0个视图，其他对象若干（按1周1人计算），人工适配 | M14: =ROUND((3200/100+2200/15+50/25+10/1+5*2)/5/4/2,2) | N14: 3200张表，2200个函数，50个视图，10个plpythonu函数，其他对象若干（按1周2人计算），使用工具，假设效率提升1倍 | O14: 21 | P14: 5 | Q14: =O14*P14 | R14: =SUM(Q14:Q19)/4 | T14: 1 | U14: 1 | V14: 1 | W14: 1 | X14: 1 | Y14: 1
A15: 11 | C15: 数据迁移阶段 | D15: 将现有数仓的业务数据迁移到新数仓中，包括数据清洗、转换、加载等过程。 | G15: 假设300-500GB/h，需注意避开交易时间及原系统高频业务时间等窗口期。 | H15: 1）硬件资源或成为瓶颈，如：网络、磁盘IO等。 2）窗口期的选择也需要综合考虑。 | I15: =ROUND(70*1024/300/8/5/4,2) | J15: 70TB，每天8h可用 | K15: =ROUND(18*1024/300/8/5/4,2) | L15: 18T，假设每天8h可用 | M15: =ROUND(100*1024/300/8/5/4,2) | N15: 100TB，每天8h可用 | O15: 6 | P15: 1 | Q15: =O15*P15 | W15: 1 | X15: 1 | Y15: 1
A16: 12 | C16: 应用迁移阶段 | D16: 根据新数仓的特性，进行数据应用及数仓组件的适配改造，包括调度系统、数据同步组件（ETL）、BI应用、数据服务组件等。 | G16: 根据应用系统的复杂度进行评估，如：假设每人每天平均可适配30个调度任务或10个BI报表。 | H16: 应用部分若适配度低，则需要增加工作量。 | I16: =ROUND(1600/30/5/4,2) | J16: 1600个任务，报表不计入 | K16: =ROUND((300/30+200/10)/5/4,2) | L16: 300个任务，200个报表 | M16: =ROUND((2000/30+1500/10)/5/4,2) | N16: 2000个任务，1500个报表 | O16: 11 | P16: 1 | Q16: =O16*P16 | U16: 1 | V16: 1 | W16: 1 | X16: 1 | Y16: 1
A17: 13 | C17: 业务校验阶段 | D17: 对迁移后的数据进行深度校验，确保数据的正确性和一致性，如有问题，及时修复。 | G17: 建议至少1个月进行数据的初步校验，2-3人，假设每人每天平均可校验10张表，若使用工具，假设效率提升1倍，则每人每天平均可校验20张表。 | H17: 实时数据场景、表模型变更、系统多个组件变更等，均对数据结果产生较大的影响。 | I17: =8000/10/5/4/2 | J17: 8000张表，使用工具，假设效率提升1倍 | K17: =400/10/5/4 | L17: 400张表，人工校验 | M17: =3000/10/5/4/2 | N17: 3000张表，使用工具，假设效率提升1倍 | O17: 16 | P17: 5 | Q17: =O17*P17 | V17: 1 | W17: 1 | X17: 1 | Y17: 1
A18: 14 | C18: 系统测试阶段 | D18: 对迁移后的新数仓进行全面的测试，包括性能测试、功能测试、安全测试等。 | G18: 建议不少于2周的系统测试，2-3人 | H18: 至少开展1-2次全系统组件联调测试。 | I18: =5*3*3/5/4 | J18: 3周3人 | K18: =2/4 | L18: 2周1人 | M18: =5*3*3/5/4 | N18: 3周3人 | O18: 3 | P18: 3 | Q18: =O18*P18 | Y18: 1
A19: 15 | C19: 文档编写阶段 | D19: 编写详细的迁移实施手册和用户手册，包括系统架构、操作指南、安装部署、应急回退、备份还原、双轨并行目标与计划等内容。 | G19: 建议1-2周，1-2人 | I19: =5*2/5/4 | J19: 1周2人 | K19: =5/5/4 | L19: 1周1人 | M19: =5*2/5/4 | N19: 1周2人 | O19: 1 | P19: 2 | Q19: =O19*P19 | Y19: 1
A20: 16 | B20: 系统试运行 | C20: 系统部署阶段 | D20: 在生产环境中部署数仓系统基础环境，包括MPP数据库集群、调度、ETL、BI报表、数据服务等组件，部署新数仓系统的代码脚本，并进行业务数据的迁移等工作。 | G20: 建议1-2周，1-2人 | I20: =5*2/5/4 | J20: 1周2人 | K20: =5/5/4 | L20: 1周1人 | M20: =5*2/5/4 | N20: 1周2人 | O20: 1 | P20: 2 | Q20: =O20*P20 | R20: =SUM(Q20:Q26)/4 | Z20: 1
A21: 17 | C21: 双轨并行阶段 | D21: 将新的数仓上线试运行，模拟正式上线流程，同时持续监控和对比新旧数仓的运行情况，及时发现并解决问题。 | G21: 建议3-6个月并行，1-3人 | I21: =6*2 | J21: 6个月2人 | K21: =3*1 | L21: 3个月1人 | M21: =6*2 | N21: 6个月2人 | O21: 24 | P21: 2 | Q21: =O21*P21 | Z21: 1 | AA21: 1 | AB21: 1 | AC21: 1 | AD21: 1 | AE21: 1
A22: 18 | C22: 培训支持阶段 | D22: 为业务人员、运维人员等提供新系统的使用培训，解决他们在使用新系统过程中遇到的问题。 | G22: 建议1-2周，1-2人 | I22: =5*2/5/4 | J22: 1周2人 | K22: 0 | L22: 1周2人，并行时同步进行，跳过 | M22: =5*2/5/4 | N22: 1周2人 | O22: 1 | P22: 2 | Q22: =O22*P22 | Z22: 1
A23: 19 | C23: 性能调优阶段 | D23: 根据系统运行情况和使用反馈，对新系统进行持续的优化和改进。 | G23: 建议并行期间进行调优，1-2人 | I23: 0 | J23: 3个月2人，并行时同步优化，跳过 | K23: 0 | L23: 3个月1人，并行时同步优化，跳过 | M23: 0 | N23: 6个月2人，并行时同步优化，跳过 | O23: 24 | P23: 0 | Q23: =O23*P23 | Z23: 1 | AA23: 1 | AB23: 1 | AC23: 1 | AD23: 1 | AE23: 1
A24: 20 | B24: 交付及运维支持 | C24: 单轨切换阶段 | D24: 将新数仓系统正式切换上线，替换旧数仓系统，同时进行生产环境的监控和维护。 | G24: 建议1周，1-2人 | I24: =5*2/5/4 | J24: 1周2人 | K24: =5/5/4 | L24: 1周1人 | M24: =5*2/5/4 | N24: 1周2人 | O24: 1 | P24: 2 | Q24: =O24*P24 | AE24: 1
A25: 21 | C25: 项目交付阶段 | D25: 梳理和整合项目实施过程中的材料，进行交付和验收。 | G25: 建议1周，1-2人 | I25: =5*2/5/4 | J25: 1周2人 | K25: =5/5/4 | L25: 1周1人 | M25: =5*2/5/4 | N25: 1周2人 | O25: 1 | P25: 2 | Q25: =O25*P25 | AE25: 1
A26: 22 | C26: 监控运维阶段 | D26: 对新的数仓系统进行长期的日常监控和维护，及时发现和解决问题。 | G26: 建议1年起，1-2人 | I26: - | J26: - | K26: - | L26: - | M26: - | N26: - | O26: - | P26: - | Q26: - | AF26: 1 | AG26: 1 | AH26: 1
A27: - | B27: 合计 | D27: - | E27: =ROUNDUP(SUM(E9:E26),3) | G27: - | H27: - | I27: =ROUNDUP(SUM(I9:I26),0) | J27: - | K27: =ROUNDUP(SUM(K9:K26),0) | L27: - | M27: =ROUNDUP(SUM(M9:M26),0) | N27: - | O27: - | P27: - | Q27: =SUM(Q9:Q26) | R27: =ROUNDUP(SUM(R9:R26),0) | S27: 第一阶段 | Z27: 第二阶段 | AF27: 第三阶段

Sheet 工作量预估（快捷计算）
A1: 数仓迁移工作量评估：
A2: 序号 | B2: 项目里程碑 | C2: 项目阶段 | D2: 工作内容 | E2: 工作量预估（人月）
E3: 工作量评估 | G3: 计划明细 （示例：某保险公司）
E4: 人月 | F4: 备注 | G4: 第1个月 | H4: 第2个月 | I4: 第3个月 | J4: 第4个月 | K4: 第5个月 | L4: 第6个月 | M4: 第7个月 | N4: 第8个月 | O4: 第9个月 | P4: 第10个月 | Q4: 第11个月 | R4: 第12个月 | S4: 第13个月 | T4: 第14个月 | U4: 第15个月 | V4: 第16个月 | W4: 第17个月 | X4: 第18个月
A5: 1 | B5: 产品交付部署 | C5: 环境信息调研 | D5: 调研硬件、网络、操作系统等基础信息，以及工作机情况（需要远程访问） | E5: ='评估基础数据（快捷计算）'!D17 | F5: ='评估基础数据（快捷计算）'!F17 | G5: 1
A6: 2 | C6: 集群部署规划 | D6: 设计和规划新集群的部署架构，包括IP、端口、磁盘等。 | E6: ='评估基础数据（快捷计算）'!D18 | F6: ='评估基础数据（快捷计算）'!F18 | G6: 1
A7: 3 | C7: 集群安装部署 | D7: 进行新集群的安装前检查、安装部署和参数调优等标准交付流程。 | E7: ='评估基础数据（快捷计算）'!D19 | F7: ='评估基础数据（快捷计算）'!F19 | G7: 1
A8: 4 | C8: 集群测试与交付 | D8: 对新集群进行测试和验证，确保正常运行后进行交付验收。 | E8: ='评估基础数据（快捷计算）'!D20 | F8: ='评估基础数据（快捷计算）'!F20 | G8: 1
A9: 5 | B9: 数仓迁移准备 | C9: 需求分析阶段 | D9: 调研现有数仓的业务需求和数据结构等现状，明确迁移过程中的关键业务点和数据依赖关系。 | E9: ='评估基础数据（快捷计算）'!D21 | F9: ='评估基础数据（快捷计算）'!F21 | G9: 1
A10: 6 | C10: 方案设计阶段 | D10: 根据需求分析结果，设计新的数仓架构和迁移方案、应急方案等。 | E10: ='评估基础数据（快捷计算）'!D22 | F10: ='评估基础数据（快捷计算）'!F22 | G10: 1
A11: 7 | C11: 计划制定阶段 | D11: 确定迁移目标、范围和时间表，制定详细的迁移计划，包括风险评估和资源调配。 | E11: ='评估基础数据（快捷计算）'!D23 | F11: ='评估基础数据（快捷计算）'!F23 | G11: 1
A12: 8 | C12: 基础环境准备 | D12: 部署新数仓环境所需的工具或组件，包括调度、ETL、BI报表、数据服务等组件及迁移工具。并配置好工作机开发环境及相关网络的权限。 | E12: ='评估基础数据（快捷计算）'!D24 | F12: ='评估基础数据（快捷计算）'!F24 | G12: 1
A13: 9 | C13: 预迁移验证阶段 | D13: 检查新数仓环境，根据迁移方案选择合适的业务线开展预迁移验证工作（涵盖迁移实施阶段的所有流程节点），及时发现并修复潜在问题。 | E13: ='评估基础数据（快捷计算）'!D25 | F13: ='评估基础数据（快捷计算）'!F25 | G13: 1 | H13: 1
A14: 10 | B14: 数仓迁移实施 | C14: 业务迁移阶段 | D14: 将现有数仓的业务脚本迁移到新数仓中，包括序列、表、函数、视图等对象。 | E14: ='评估基础数据（快捷计算）'!D26 | F14: ='评估基础数据（快捷计算）'!F26 | H14: 1 | I14: 1 | J14: 1 | K14: 1 | L14: 1 | M14: 1
A15: 11 | C15: 数据迁移阶段 | D15: 将现有数仓的业务数据迁移到新数仓中，包括数据清洗、转换、加载等过程。 | E15: ='评估基础数据（快捷计算）'!D27 | F15: ='评估基础数据（快捷计算）'!F27 | K15: 1 | L15: 1 | M15: 1
A16: 12 | C16: 应用迁移阶段 | D16: 根据新数仓的特性，进行数据应用及数仓组件的适配改造，包括调度系统、数据同步组件（ETL）、BI应用、数据服务组件等。 | E16: ='评估基础数据（快捷计算）'!D28 | F16: ='评估基础数据（快捷计算）'!F28 | I16: 1 | J16: 1 | K16: 1 | L16: 1 | M16: 1
A17: 13 | C17: 业务校验阶段 | D17: 对迁移后的数据进行深度校验，确保数据的正确性和一致性，如有问题，及时修复。 | E17: ='评估基础数据（快捷计算）'!D29 | F17: ='评估基础数据（快捷计算）'!F29 | J17: 1 | K17: 1 | L17: 1 | M17: 1
A18: 14 | C18: 系统测试阶段 | D18: 对迁移后的新数仓进行全面的测试，包括性能测试、功能测试、安全测试等。 | E18: ='评估基础数据（快捷计算）'!D30 | F18: ='评估基础数据（快捷计算）'!F30 | M18: 1
A19: 15 | C19: 文档编写阶段 | D19: 编写详细的迁移实施手册和用户手册，包括系统架构、操作指南、安装部署、应急回退、备份还原、双轨并行目标与计划等内容。 | E19: ='评估基础数据（快捷计算）'!D31 | F19: ='评估基础数据（快捷计算）'!F31 | M19: 1
A20: 16 | B20: 系统试运行 | C20: 系统部署阶段 | D20: 在生产环境中部署数仓系统基础环境，包括MPP数据库集群、调度、ETL、BI报表、数据服务等组件，部署新数仓系统的代码脚本，并进行业务数据的迁移等工作。 | E20: ='评估基础数据（快捷计算）'!D32 | F20: ='评估基础数据（快捷计算）'!F32 | N20: 1
A21: 17 | C21: 双轨并行阶段 | D21: 将新的数仓上线试运行，模拟正式上线流程，同时持续监控和对比新旧数仓的运行情况，及时发现并解决问题。 | E21: ='评估基础数据（快捷计算）'!D33 | F21: ='评估基础数据（快捷计算）'!F33 | N21: 1 | O21: 1 | P21: 1 | Q21: 1 | R21: 1 | S21: 1
A22: 18 | C22: 培训支持阶段 | D22: 为业务人员、运维人员等提供新系统的使用培训，解决他们在使用新系统过程中遇到的问题。 | E22: ='评估基础数据（快捷计算）'!D34 | F22: ='评估基础数据（快捷计算）'!F34 | N22: 1
A23: 19 | C23: 性能调优阶段 | D23: 根据系统运行情况和使用反馈，对新系统进行持续的优化和改进。 | E23: ='评估基础数据（快捷计算）'!D35 | F23: ='评估基础数据（快捷计算）'!F35 | N23: 1 | O23: 1 | P23: 1 | Q23: 1 | R23: 1 | S23: 1
A24: 20 | B24: 交付及运维支持 | C24: 单轨切换阶段 | D24: 将新数仓系统正式切换上线，替换旧数仓系统，同时进行生产环境的监控和维护。 | E24: ='评估基础数据（快捷计算）'!D36 | F24: ='评估基础数据（快捷计算）'!F36 | S24: 1
A25: 21 | C25: 项目交付阶段 | D25: 梳理和整合项目实施过程中的材料，进行交付和验收。 | E25: ='评估基础数据（快捷计算）'!D37 | F25: ='评估基础数据（快捷计算）'!F37 | S25: 1
A26: 22 | C26: 监控运维阶段 | D26: 对新的数仓系统进行长期的日常监控和维护，及时发现和解决问题。 | E26: - | F26: - | T26: 1 | U26: 1 | V26: 1
A27: - | B27: 合计 | D27: - | E27: =ROUNDUP(SUM(E9:E26),3) | G27: 第一阶段 | N27: 第二阶段 | T27: 第三阶段

Sheet 评估基础数据（快捷计算）
A1: 数据仓库迁移评估：代码迁移、数据迁移、数据校验
A2: 评估项目 | B2: 评估基准（每人天） | C2: 调研数据 | D2: 评估结果（人天） | E2: 评估结果（人月） | F2: 备注说明
A3: 汇总 | B3: - | C3: - | D3: =SUM(D4:D10) | E3: =ROUND(D3/21.75,2)
A4: 表个数（无主键） | B4: 180 | C4: =43484-C6-C5 | D4: =ROUNDUP(C4/B4,0) | E4: =ROUND(D4/21.75,2) | F4: 工具+人工
A5: 表个数（分区表） | B5: 150 | C5: 406 | D5: =ROUNDUP(C5/B5,0) | E5: =ROUND(D5/21.75,2) | F5: 工具+人工
A6: 表个数（有主键） | B6: 300 | C6: 1593 | D6: =ROUNDUP(C6/B6,0) | E6: =ROUND(D6/21.75,2) | F6: 工具+人工
A7: 数据量(TB) | B7: =ROUND((((300/1024/1024)/(1/60/60))*8),2) | C7: 106.22 | D7: =ROUNDUP(C7/B7,0) | E7: =ROUND(D7/21.75,2) | F7: 提供工具：300MB/s（≈1T/h）,假设8h/天可用
A8: 函数个数 | B8: 10 | C8: =427+2266+530 | D8: =ROUNDUP(C8/B8,0) | E8: =ROUND(D8/21.75,2)
A9: 视图个数 | B9: 25 | C9: 2075 | D9: =ROUNDUP(C9/B9,0) | E9: =ROUND(D9/21.75,2)
A10: 业务校验 | B10: 50 | C10: 43484 | D10: =ROUNDUP(C10/B10,0) | E10: =ROUND(D10/21.75,2)
A11: 调度任务数 | B11: 30 | D11: =ROUNDUP(C11/B11,0) | E11: =ROUND(D11/21.75,2)
A12: ETL任务数 | B12: 10 | D12: =ROUNDUP(C12/B12,0) | E12: =ROUND(D12/21.75,2)
A13: 报表个数 | B13: 20 | D13: =ROUNDUP(C13/B13,0) | E13: =ROUND(D13/21.75,2)
A15: 项目评估：
A16: 里程碑 | B16: 项目阶段 | C16: 评估结果（人天） | D16: 评估结果（人月） | E16: 方案选择 （1甲方、2乙方、3原厂） | F16: 备注说明
A17: 产品交付部署 | B17: 环境信息调研 | C17: =IF(E17="方案3",0,3*1*1) | D17: =ROUND(C17/21.75,2) | E17: 方案2 | F17: =IF(E17="方案3","原厂负责交付部署，由原厂评估","乙方负责交付部署，预估3天1人")
B18: 集群部署规划 | C18: =IF(E18="方案3",0,3*1*1) | D18: =ROUND(C18/21.75,2) | E18: 方案2 | F18: =IF(E18="方案3","原厂负责交付部署，由原厂评估","乙方负责交付部署，预估3天1人")
B19: 集群安装部署 | C19: =IF(E19="方案3",0,5*1*2) | D19: =ROUND(C19/21.75,2) | E19: 方案2 | F19: =IF(E19="方案3","原厂负责交付部署，由原厂评估","乙方负责交付部署，预估1周2人")
B20: 集群测试与交付 | C20: =IF(E20="方案3",0,5*1*1) | D20: =ROUND(C20/21.75,2) | E20: 方案2 | F20: =IF(E20="方案3","原厂负责交付部署，由原厂评估","乙方负责交付部署，预估1周1人")
A21: 数仓迁移准备 | B21: 调研分析阶段 | C21: =5*1*2 | D21: =ROUND(C21/21.75,2) | F21: 1周2人
B22: 方案设计阶段 | C22: =5*1*1 | D22: =ROUND(C22/21.75,2) | F22: 1周1人
B23: 计划制定阶段 | C23: =2*1 | D23: =ROUND(C23/21.75,2) | F23: 2天1人
B24: 环境准备阶段 | C24: =5*1*2 | D24: =ROUND(C24/21.75,2) | F24: 1周2人
B25: 预迁移验证阶段 | C25: 0 | D25: =ROUND(C25/21.75,2) | F25: 2周3人（非必选）
A26: 数仓迁移实施 | B26: 业务迁移阶段 | C26: =SUM(D4,D5,D6,D8,D9)+5 | D26: =ROUND(C26/21.75,2) | F26: ="表"&C4+C5+C6&"、函数"&C8&"、视图"&C9&"，工具+人工"
B27: 数据迁移阶段 | C27: =IF(E27="方案1",10,D7) | D27: =ROUND(C27/21.75,2) | E27: 方案1 | F27: =IF(E27="方案1","甲方负责，乙方提供技术支持","乙方负责，数据"&C7&"T，"&F7)
B28: 应用迁移阶段 | C28: =IF(E28="方案1",60,SUM(D11:D13)) | D28: =ROUND(C28/21.75,2) | E28: 方案1 | F28: =IF(E28="方案1","甲方负责（含调度、ETL、报表等数据库外围），乙方提供技术支持","乙方负责，甲方参与梳理和评审，根据工作量评估")
B29: 业务校验阶段 | C29: =IF(E29="方案1",60,D10) | D29: =ROUND(C29/21.75,2) | E29: 方案1 | F29: =IF(E29="方案1","甲方负责，乙方提供工具及技术支持","乙方负责，甲方参与评审，根据工作量评估")
B30: 系统测试阶段 | C30: =5*2*3 | D30: =ROUND(C30/21.75,2) | F30: 2周3人
B31: 文档编写阶段 | C31: =3*2 | D31: =ROUND(C31/21.75,2) | F31: 3天2人
A32: 系统试运行 | B32: 系统部署阶段 | C32: =2*2 | D32: =ROUND(C32/21.75,2) | F32: 2天2人
B33: 双轨并行阶段 | C33: =21.75*2*3 | D33: =ROUND(C33/21.75,2) | F33: 3个月2人
B34: 培训支持阶段 | C34: 3 | D34: =ROUND(C34/21.75,2) | F34: 假设3次
B35: 性能调优阶段 | C35: 0 | D35: =ROUND(C35/21.75,2) | F35: 复用并行期资源
A36: 项目交付 | B36: 单轨切换阶段 | C36: =2*2 | D36: =ROUND(C36/21.75,2) | F36: 2天2人
B37: 项目交付阶段 | C37: =2*2 | D37: =ROUND(C37/21.75,2) | F37: 2天2人
A38: 合计（不含部署） | C38: =SUM(C21:C37) | D38: =SUM(D21:D37)
A39: 合计（含部署） | C39: =SUM(C17:C37) | D39: =SUM(D17:D37)
A40: 合计（不含部署）占比1/3 | C40: =ROUNDUP((C26+C27+C28+C29)/3+SUM(C21:C25)+SUM(C30:C37),2) | D40: =ROUNDUP((D26+D27+D28+D29)/3+SUM(D21:D25)+SUM(D30:D37),2)
A41: 合计（含部署）占比1/3 | C41: =ROUNDUP((C26+C27+C28+C29)/3+SUM(C17:C25)+SUM(C30:C37),2) | D41: =ROUNDUP((D26+D27+D28+D29)/3+SUM(D17:D25)+SUM(D30:D37),2)
...
